Workbook

Sheet Table_of_Contents_&_Acronym
A1: Future Growth & Industry Trends Analysis
A2: Individual Analysis supporting the project: Using Data to Support Career Decision-Making in Computer Science
A5: Tab | B5: Content | D5: Acronyms and Abbreviations
A6: 01_Overview | B6: Research purpose, main question, supporting questions and analytical framework | D6: Acronym | E6: Full term
A7: 02_Raw_Baseline | B7: Original Baseline employment projection data | D7: AI | E7: Artificial Intelligence
A8: 03_Raw_Technical | B8: Original Technical Opportunities scenario data | D8: APS | E8: Annual Population Survey
A9: 04_Raw_HumanCentric | B9: Original Human-Centric scenario data | D9: CS | E9: Computer Science
A10: 05_Data_Preparation | B10: Data cleaning, preparation and allocation steps before analysis | D10: DfE | E10: Department for Education
A11: 06_Career_Area_Map | B11: Mapping of Standard Occupational Classification (SOC) occupations to the five Computer Science Career Areas | D11: ID | E11: Identifier
A12: 07_Analysis_Base | B12: Main prepared analytical dataset used across Q1–Q4 | D12: IT | E12: Information Technology
A13: 08_WEF_Technology | B13: World Economic Forum (WEF) technology trends and United Kingdom (UK)/Global employer expectations | D13: MA | E13: Moving Average
A14: 09_WEF_Jobs_Outlook | B14: WEF jobs outlook evidence, including growth and structural change | D14: ML | E14: Machine Learning
A15: 10_WEF_AI_Strategy | B15: WEF evidence on organisational Artificial Intelligence (AI) strategies and workforce responses | D15: MSE | E15: Mean Squared Error
A16: 11_WEF_Skills_Outlook | B16: WEF evidence on skills expected to grow in importance | D16: N/A | E16: Not Applicable
A17: 12_WEF_Fastest_Growing | B17: WEF fastest-growing jobs and their relevance to the Career Areas | D17: ONS | E17: Office for National Statistics
... A26: 19_Visual_Summary | B26: Visual summary of the main analytical results | D26: YoY | E26: Year-on-Year
A27: 20_Main_Formulas | B27: Key formulas and analytical logic used throughout the workbook
A28: 21_References | B28: External datasets and supporting sources used in the analysis

Sheet 01_Overview
A1: Future Growth & Industry Trends Analysis
A2: Individual Analysis supporting the project: Using Data to Support Career Decision-Making in Computer Science
A4: Purpose
A5: This workbook analyses future employment growth, employment projections, technology trends and curriculum alignment across five Computer Science Career Areas. It combines official UK employment projections with structured evidence from the World Economic Forum and the supporting Career Map methodology to identify which areas show stronger future potential and what these findings imply for students making career decisions.
A7: Main Research Question | D7: Analytical Framework
A8: Which Computer Science Career Areas show the strongest future growth potential?
D9: Research Question | E9: Analytics Type | F9: Method
A10: Supporting Questions
A11: Q1. How do employment growth and job creation differ across the five Career Areas? | D11: Q1 — Growth and job creation | E11: Descriptive | F11: Descriptive Analysis
A12: Q2. How do employment projections change over time and across future scenarios? | D12: Q2 — Employment projections and scenarios | E12: Predictive | F12: Time Series Analysis + Exploratory Forecasting
A13: Q3. Which technology trends are linked to the future outlook of Computer Science careers, and how does the UK compare globally? | D13: Q3 — UK vs Global technology expectations | E13: Diagnostic | F13: Descriptive comparison + Simple Linear Regression
A14: Q4. Do high-growth occupations also show strong curriculum alignment, or important skills gaps? | D14: Q4 — Growth × curriculum alignment/gaps | E14: Diagnostic | F14: Cluster Analysis
A15: Decision-Support Question | D15: Decision-Support Question | E15: Prescriptive | F15: Decision Analysis
A16: What do these findings imply for students choosing a Computer Science career with stronger future potential?
D17: Methodological Note: Q2 combines official Department for Education (DfE) long-term employment projections with an exploratory short-term 2026 forecast based on Office for National Statistics (ONS) Annual Population Survey (APS) employment estimates for 2021–2025. Moving Average and Simple Exponential Smoothing models were compared using Mean Squared Error (MSE). Due to the short time series, the forecast is exploratory and is not extended to 2035.
A18: Data Sources
A19: Evidence | B19: Role in the Analysis
A20: UK Labour Market and Skills Projections 2020–2035 | B20: Employment levels and future scenarios at Standard Occupational Classification 2020 (SOC2020) Unit Group level
A21: World Economic Forum (WEF) Future of Jobs Report 2025 – UK Economy Profile + Global Report Evidence | B21: Technology trends, jobs outlook, AI strategy, skills and global fastest-growing occupations.
A22: Career Map & Curriculum Alignment Supporting Workbook | B22: SOC-to-Career-Area classification, mixed-SOC methodology and curriculum alignment/gap evidence
A24: WEF evidence was manually extracted and structured from the original PDF/report and is therefore treated as Extracted / Structured Data, rather than raw data.
A26: Analytical Stages
A27: Analytical Workflow
A28: Sources → Raw Scenarios → Data Preparation → Career Area Mapping → Analysis Base → WEF Structured Evidence → Descriptive → Predictive → Diagnostic → Prescriptive → Key Findings → Visual Summary
A30: Workbook Section | B30: Sheets
A31: Sources & Preparation | B31: 21_References – 07_Analysis_Base
A32: WEF Evidence | B32: 08_WEF_Technology – 12_WEF_Fastest_Growing
A33: Analytical Methods | B33: 13_Descriptive_Q1 – 17_Prescriptive_Analysis
A34: Final Communication | B34: 18_Key_Findings – 19_Visual_Summary
A36: Career Areas in Scope
A37: Career Area | B37: Main SOC Coverage
A38: Software Development & Testing | B38: 2134, 2136 + proportional share of 2139
A39: Data, Analytics & Databases | B39: 3544, 3133 + proportional share of 2133
A40: Cybersecurity | B40: 2135
A41: Web, Applications & UX/UI | B41: 2141 + proportional share of 2139
A42: IT Infrastructure, Networks & Support | B42: 2137, 3131, 3132 + proportional share of 2133
A43: Supporting classification: Cross-functional / Mixed IT is retained for occupations within mixed SOC Unit Groups that cannot be assigned exclusively to one of the five Career Areas.
A47: Key Methodological Notes
A48: Mixed SOC Unit Groups: SOC 2133 and 2139 contain occupations spanning multiple Career Areas. Because official employment projections are available at Unit Group level rather than Extended SOC Sub-Unit level, validated Adzuna vacancy-search proportions are used as a methodological proxy for proportional Career Area allocation. These proportions are not official SOC employment weights.
A49: Important distinction: Proportional allocation of 2133 and 2139 is used for Career Area employment and forecast analysis. For curriculum alignment and gap analysis at SOC Unit Group level, Overall Alignment is not proportionally divided; 2133 and 2139 remain mixed methodological cases.

Sheet 02_Raw_Baseline
A1: Table 2: Employment by occupation (SOC2020 unit group), baseline scenario, 2021 to 2035, United Kingdom
A2: SOC2020 sub-major group | B2: SOC2020 unit group | C2: Occupation description | D2: 2021 | E2: 2022 | F2: 2023 | G2: 2024 | H2: 2025 | I2: 2026 | J2: 2027 | K2: 2028 | L2: 2029 | M2: 2030 | N2: 2031 | O2: 2032 | P2: 2033 | Q2: 2034 | R2: 2035
A3: 11 | B3: 1111 | C3: Chief executives and senior officials | D3: 141827.42 | E3: 143276.75 | F3: 144998.02 | G3: 146818.83 | H3: 148315.69 | I3: 149722.57 | J3: 151076.34 | K3: 152440.7 | L3: 153811.24 | M3: 155249.46 | N3: 156682.28 | O3: 158128.11 | P3: 159591.11 | Q3: 161061 | R3: 162543.89
A4: 11 | B4: 1112 | C4: Elected officers and representatives | D4: 11808.071 | E4: 11928.737 | F4: 12072.044 | G4: 12223.639 | H4: 12348.262 | I4: 12465.394 | J4: 12578.105 | K4: 12691.697 | L4: 12805.803 | M4: 12925.545 | N4: 13044.836 | O4: 13165.211 | P4: 13287.016 | Q4: 13409.393 | R4: 13532.854
A5: 11 | B5: 1121 | C5: Production managers and directors in manufacturing | D5: 258484.04 | E5: 261125.49 | F5: 264262.54 | G5: 267581.01 | H5: 270309.07 | I5: 272873.15 | J5: 275340.44 | K5: 277827.01 | L5: 280324.86 | M5: 282946.05 | N5: 285557.39 | O5: 288192.46 | P5: 290858.82 | Q5: 293537.72 | R5: 296240.33
A6: 11 | B6: 1122 | C6: Production managers and directors in construction | D6: 168634.73 | E6: 170358.01 | F6: 172404.62 | G6: 174569.59 | H6: 176349.37 | I6: 178022.17 | J6: 179631.83 | K6: 181254.07 | L6: 182883.66 | M6: 184593.72 | N6: 186297.36 | O6: 188016.47 | P6: 189756 | Q6: 191503.72 | R6: 193266.9
A7: 11 | B7: 1123 | C7: Production managers and directors in mining and energy | D7: 28061.589 | E7: 28348.35 | F7: 28688.916 | G7: 29049.176 | H7: 29345.34 | I7: 29623.702 | J7: 29891.556 | K7: 30161.504 | L7: 30432.675 | M7: 30717.238 | N7: 31000.731 | O7: 31286.8 | P7: 31576.265 | Q7: 31867.092 | R7: 32160.493
A8: 11 | B8: 1131 | C8: Financial managers and directors | D8: 332477.63 | E8: 335875.22 | F8: 339910.29 | G8: 344178.7 | H8: 347687.69 | I8: 350985.77 | J8: 354159.34 | K8: 357357.72 | L8: 360570.59 | M8: 363942.13 | N8: 367301 | O8: 370690.38 | P8: 374120.01 | Q8: 377565.77 | R8: 381042.03
A9: 11 | B9: 1132 | C9: Marketing, sales and advertising directors | D9: 268296.36 | E9: 271038.08 | F9: 274294.22 | G9: 277738.67 | H9: 280570.28 | I9: 283231.7 | J9: 285792.65 | K9: 288373.61 | L9: 290966.28 | M9: 293686.98 | N9: 296397.45 | O9: 299132.55 | P9: 301900.12 | Q9: 304680.72 | R9: 307485.92
A10: 11 | B10: 1133 | C10: Public relations and communications directors | D10: 13905.976 | E10: 14048.081 | F10: 14216.849 | G10: 14395.376 | H10: 14542.141 | I10: 14680.084 | J10: 14812.819 | K10: 14946.592 | L10: 15080.972 | M10: 15221.987 | N10: 15362.473 | O10: 15504.235 | P10: 15647.68 | Q10: 15791.8 | R10: 15937.196
A11: 11 | B11: 1134 | C11: Purchasing managers and directors | D11: 58443.659 | E11: 59040.895 | F11: 59750.188 | G11: 60500.499 | H11: 61117.317 | I11: 61697.06 | J11: 62254.918 | K11: 62817.136 | L11: 63381.902 | M11: 63974.559 | N11: 64564.988 | O11: 65160.781 | P11: 65763.648 | Q11: 66369.353 | R11: 66980.417
A12: 11 | B12: 1135 | C12: Charitable organisation managers and directors | D12: 52923.213 | E12: 53464.035 | F12: 54106.331 | G12: 54785.769 | H12: 55344.324 | I12: 55869.306 | J12: 56374.47 | K12: 56883.582 | L12: 57395.002 | M12: 57931.678 | N12: 58466.336 | O12: 59005.852 | P12: 59551.774 | Q12: 60100.265 | R12: 60653.61
A13: 11 | B13: 1136 | C13: Human resource managers and directors | D13: 238409.85 | E13: 240846.16 | F13: 243739.59 | G13: 246800.34 | H13: 249316.53 | I13: 251681.48 | J13: 253957.16 | K13: 256250.62 | L13: 258554.48 | M13: 260972.11 | N13: 263380.65 | O13: 265811.08 | P13: 268270.36 | Q13: 270741.22 | R13: 273233.94
A14: 11 | B14: 1137 | C14: Information technology directors | D14: 187680.61 | E14: 189598.51 | F14: 191876.27 | G14: 194285.75 | H14: 196266.55 | I14: 198128.28 | J14: 199919.73 | K14: 201725.19 | L14: 203538.83 | M14: 205442.03 | N14: 207338.08 | O14: 209251.36 | P14: 211187.35 | Q14: 213132.45 | R14: 215094.77
... A414: 92 | B414: 9269 | C414: Other elementary services occupations n.e.c. | D414: 30781.396 | E414: 30708.604 | F414: 30686.517 | G414: 30687.589 | H414: 30620.005 | I414: 30524.894 | J414: 30414.593 | K414: 30300.63 | L414: 30183.582 | M414: 30073.841 | N414: 29959.807 | O414: 29844.017 | P414: 29728.133 | Q414: 29609.498 | R414: 29489.128

Sheet 03_Raw_Technical
A1: Table 6: Employment by occupation (SOC2020 unit group), technical opportunities scenario, 2021 to 2035, United Kingdom
A2: SOC2020 sub-major group | B2: SOC2020 unit group | C2: Occupation description | D2: 2021 | E2: 2022 | F2: 2023 | G2: 2024 | H2: 2025 | I2: 2026 | J2: 2027 | K2: 2028 | L2: 2029 | M2: 2030 | N2: 2031 | O2: 2032 | P2: 2033 | Q2: 2034 | R2: 2035
A3: 11 | B3: 1111 | C3: Chief executives and senior officials | D3: 142155.58 | E3: 143848.41 | F3: 145507.23 | G3: 147045.66 | H3: 148143.43 | I3: 149155.19 | J3: 150105.55 | K3: 151057.38 | L3: 152000.13 | M3: 152997.91 | N3: 153957.82 | O3: 154910.51 | P3: 155860.82 | Q3: 156799.39 | R3: 157736.64
A4: 11 | B4: 1112 | C4: Elected officers and representatives | D4: 11835.393 | E4: 11976.332 | F4: 12114.439 | G4: 12242.524 | H4: 12333.921 | I4: 12418.156 | J4: 12497.28 | K4: 12576.526 | L4: 12655.017 | M4: 12738.088 | N4: 12818.007 | O4: 12897.325 | P4: 12976.444 | Q4: 13054.586 | R4: 13132.619
A5: 11 | B5: 1121 | C5: Production managers and directors in manufacturing | D5: 259082.13 | E5: 262167.35 | F5: 265190.59 | G5: 267994.41 | H5: 269995.14 | I5: 271839.09 | J5: 273571.14 | K5: 275305.88 | L5: 277024.07 | M5: 278842.53 | N5: 280592 | O5: 282328.31 | P5: 284060.27 | Q5: 285770.83 | R5: 287479
A6: 11 | B6: 1122 | C6: Production managers and directors in construction | D6: 169024.92 | E6: 171037.72 | F6: 173010.08 | G6: 174839.29 | H6: 176144.56 | I6: 177347.55 | J6: 178477.54 | K6: 179609.28 | L6: 180730.23 | M6: 181916.59 | N6: 183057.94 | O6: 184190.71 | P6: 185320.63 | Q6: 186436.61 | R6: 187551.01
A7: 11 | B7: 1123 | C7: Production managers and directors in mining and energy | D7: 28126.518 | E7: 28461.456 | F7: 28789.666 | G7: 29094.055 | H7: 29311.258 | I7: 29511.442 | J7: 29699.477 | K7: 29887.804 | L7: 30074.334 | M7: 30271.751 | N7: 30461.676 | O7: 30650.174 | P7: 30838.199 | Q7: 31023.902 | R7: 31209.344
A8: 11 | B8: 1131 | C8: Financial managers and directors | D8: 333246.93 | E8: 337215.32 | F8: 341104 | G8: 344710.44 | H8: 347283.89 | I8: 349655.69 | J8: 351883.56 | K8: 354114.88 | L8: 356324.92 | M8: 358663.94 | N8: 360914.21 | O8: 363147.55 | P8: 365375.3 | Q8: 367575.54 | R8: 369772.68
A9: 11 | B9: 1132 | C9: Marketing, sales and advertising directors | D9: 268917.15 | E9: 272119.49 | F9: 275257.5 | G9: 278167.76 | H9: 280244.43 | I9: 282158.38 | J9: 283956.18 | K9: 285756.77 | L9: 287540.19 | M9: 289427.68 | N9: 291243.56 | O9: 293045.78 | P9: 294843.49 | Q9: 296618.99 | R9: 298392
A10: 11 | B10: 1133 | C10: Public relations and communications directors | D10: 13938.151 | E10: 14104.131 | F10: 14266.776 | G10: 14417.616 | H10: 14525.252 | I10: 14624.453 | J10: 14717.634 | K10: 14810.96 | L10: 14903.396 | M10: 15001.226 | N10: 15095.344 | O10: 15188.754 | P10: 15281.93 | Q10: 15373.956 | R10: 15465.852
A11: 11 | B11: 1134 | C11: Purchasing managers and directors | D11: 58578.887 | E11: 59276.46 | F11: 59960.021 | G11: 60593.969 | H11: 61046.336 | I11: 61463.256 | J11: 61854.876 | K11: 62247.103 | L11: 62635.589 | M11: 63046.747 | N11: 63442.303 | O11: 63834.886 | P11: 64226.485 | Q11: 64613.247 | R11: 64999.465
A12: 11 | B12: 1135 | C12: Charitable organisation managers and directors | D12: 53045.668 | E12: 53677.35 | F12: 54296.343 | G12: 54870.41 | H12: 55280.048 | I12: 55657.587 | J12: 56012.215 | K12: 56367.393 | L12: 56719.184 | M12: 57091.505 | N12: 57449.698 | O12: 57805.198 | P12: 58159.808 | Q12: 58510.037 | R12: 58859.774
A13: 11 | B13: 1136 | C13: Human resource managers and directors | D13: 238961.49 | E13: 241807.1 | F13: 244595.56 | G13: 247181.63 | H13: 249026.98 | I13: 250727.72 | J13: 252325.26 | K13: 253925.28 | L13: 255510.03 | M13: 257187.27 | N13: 258800.87 | O13: 260402.34 | P13: 261999.79 | Q13: 263577.51 | R13: 265153.02
A14: 11 | B14: 1137 | C14: Information technology directors | D14: 188114.87 | E14: 190354.99 | F14: 192550.11 | G14: 194585.91 | H14: 196038.6 | I14: 197377.46 | J14: 198635.08 | K14: 199894.64 | L14: 201142.19 | M14: 202462.54 | N14: 203732.79 | O14: 204993.5 | P14: 206251.04 | Q14: 207493.05 | R14: 208733.32
... A414: 92 | B414: 9269 | C414: Other elementary services occupations n.e.c. | D414: 30851.148 | E414: 30881.867 | F414: 30893.519 | G414: 30861.376 | H414: 30726.027 | I414: 30563.409 | J414: 30384.773 | K414: 30201.658 | L414: 30013.108 | M414: 29829.214 | N414: 29641.627 | O414: 29449.672 | P414: 29254.858 | Q414: 29054.584 | R414: 28850.586

Sheet 04_Raw_HumanCentric
A1: Table 8: Employment by occupation (SOC2020 unit group), human-centric scenario, 2021 to 2035, United Kingdom
A2: SOC2020 sub-major group | B2: SOC2020 unit group | C2: Occupation description | D2: 2021 | E2: 2022 | F2: 2023 | G2: 2024 | H2: 2025 | I2: 2026 | J2: 2027 | K2: 2028 | L2: 2029 | M2: 2030 | N2: 2031 | O2: 2032 | P2: 2033 | Q2: 2034 | R2: 2035
A3: 11 | B3: 1111 | C3: Chief executives and senior officials | D3: 142099.52 | E3: 143708.95 | F3: 145315.58 | G3: 146809.29 | H3: 147841.24 | I3: 148788.04 | J3: 149676.09 | K3: 150568.35 | L3: 151453.8 | M3: 152396.57 | N3: 153304.52 | O3: 154208.16 | P3: 155111.23 | Q3: 156005.66 | R3: 156901.21
A4: 11 | B4: 1112 | C4: Elected officers and representatives | D4: 11830.725 | E4: 11964.721 | F4: 12098.483 | G4: 12222.844 | H4: 12308.762 | I4: 12387.588 | J4: 12461.525 | K4: 12535.811 | L4: 12609.531 | M4: 12688.022 | N4: 12763.615 | O4: 12838.849 | P4: 12914.036 | Q4: 12988.503 | R4: 13063.063
A5: 11 | B5: 1121 | C5: Production managers and directors in manufacturing | D5: 258979.95 | E5: 261913.18 | F5: 264841.3 | G5: 267563.62 | H5: 269444.39 | I5: 271169.94 | J5: 272788.45 | K5: 274414.6 | L5: 276028.37 | M5: 277746.58 | N5: 279401.34 | O5: 281048.25 | P5: 282694.12 | Q5: 284324.24 | R5: 285956.4
A6: 11 | B6: 1122 | C6: Production managers and directors in construction | D6: 168958.26 | E6: 170871.9 | F6: 172782.2 | G6: 174558.24 | H6: 175785.25 | I6: 176911 | J6: 177966.91 | K6: 179027.81 | L6: 180080.63 | M6: 181201.59 | N6: 182281.16 | O6: 183355.6 | P6: 184429.36 | Q6: 185492.85 | R6: 186557.67
A7: 11 | B7: 1123 | C7: Production managers and directors in mining and energy | D7: 28115.426 | E7: 28433.864 | F7: 28751.746 | G7: 29047.288 | H7: 29251.468 | I7: 29438.797 | J7: 29614.506 | K7: 29791.045 | L7: 29966.239 | M7: 30152.772 | N7: 30332.416 | O7: 30511.208 | P7: 30689.888 | Q7: 30866.857 | R7: 31044.047
A8: 11 | B8: 1131 | C8: Financial managers and directors | D8: 333115.5 | E8: 336888.4 | F8: 340654.72 | G8: 344156.33 | H8: 346575.49 | I8: 348794.99 | J8: 350876.82 | K8: 352968.47 | L8: 355044.2 | M8: 357254.26 | N8: 359382.72 | O8: 361501.07 | P8: 363618.09 | Q8: 365714.84 | R8: 367814.22
A9: 11 | B9: 1132 | C9: Marketing, sales and advertising directors | D9: 268811.1 | E9: 271855.68 | F9: 274894.95 | G9: 277720.61 | H9: 279672.78 | I9: 281463.83 | J9: 283143.78 | K9: 284831.67 | L9: 286506.69 | M9: 288290.13 | N9: 290007.71 | O9: 291717.13 | P9: 293425.49 | Q9: 295117.48 | R9: 296811.6
A10: 11 | B10: 1133 | C10: Public relations and communications directors | D10: 13932.655 | E10: 14090.457 | F10: 14247.984 | G10: 14394.441 | H10: 14495.622 | I10: 14588.454 | J10: 14675.527 | K10: 14763.011 | L10: 14849.829 | M10: 14942.265 | N10: 15031.289 | O10: 15119.889 | P10: 15208.434 | Q10: 15296.132 | R10: 15383.939
A11: 11 | B11: 1134 | C11: Purchasing managers and directors | D11: 58555.785 | E11: 59218.993 | F11: 59881.045 | G11: 60496.567 | H11: 60921.811 | I11: 61311.961 | J11: 61677.908 | K11: 62045.584 | L11: 62410.46 | M11: 62798.95 | N11: 63173.094 | O11: 63545.463 | P11: 63917.598 | Q11: 64286.169 | R11: 64655.203
A12: 11 | B12: 1135 | C12: Charitable organisation managers and directors | D12: 53024.748 | E12: 53625.311 | F12: 54224.827 | G12: 54782.209 | H12: 55167.285 | I12: 55520.583 | J12: 55851.963 | K12: 56184.91 | L12: 56515.32 | M12: 56867.114 | N12: 57205.918 | O12: 57543.113 | P12: 57880.097 | Q12: 58213.854 | R12: 58548.03
A13: 11 | B13: 1136 | C13: Human resource managers and directors | D13: 238867.24 | E13: 241572.68 | F13: 244273.39 | G13: 246784.3 | H13: 248519 | I13: 250110.54 | J13: 251603.36 | K13: 253103.22 | L13: 254591.66 | M13: 256176.44 | N13: 257702.68 | O13: 259221.69 | P13: 260739.74 | Q13: 262243.26 | R13: 263748.67
A14: 11 | B14: 1137 | C14: Information technology directors | D14: 188040.68 | E14: 190170.44 | F14: 192296.5 | G14: 194273.13 | H14: 195638.72 | I14: 196891.61 | J14: 198066.78 | K14: 199247.5 | L14: 200419.23 | M14: 201666.79 | N14: 202868.28 | O14: 204064.07 | P14: 205259.11 | Q14: 206442.71 | R14: 207627.79
... A414: 92 | B414: 9269 | C414: Other elementary services occupations n.e.c. | D414: 30849.914 | E414: 30884.128 | F414: 30906.882 | G414: 30888.576 | H414: 30762.732 | I414: 30610.354 | J414: 30442.618 | K414: 30270.737 | L414: 30093.62 | M414: 29921.742 | N414: 29746.787 | O414: 29567.766 | P414: 29385.872 | Q414: 29198.676 | R414: 29007.964

Sheet 05_Data_Preparation
A1: Data Selection
A2: The original government projection datasets contain all SOC2020 Unit Groups. For this analysis, only the 11 Unit Groups previously identified as relevant to the five Computer Science Career Areas were selected. The same SOC selection was applied consistently to the Baseline, Technical Opportunities and Human-Centric scenarios for the full 2021–2035 period. The complete source datasets remain preserved in 02_Raw_Baseline, 03_Raw_Technical and 04_Raw_HumanCentric.
A3: Selected SOC2020 Unit Groups: 2133, 2134, 2135, 2136, 2137, 2139, 2141, 3131, 3132, 3133, 3544.
A5: Table 2: Employment by occupation (SOC2020 unit group), baseline scenario, 2021 to 2035, United Kingdom
A6: SOC2020 sub-major group | B6: SOC2020 unit group | C6: Occupation description | D6: 2021 | E6: 2022 | F6: 2023 | G6: 2024 | H6: 2025 | I6: 2026 | J6: 2027 | K6: 2028 | L6: 2029 | M6: 2030 | N6: 2031 | O6: 2032 | P6: 2033 | Q6: 2034 | R6: 2035
A7: 21 | B7: 2133 | C7: IT business analysts, architects and systems designers | D7: 141540.94 | E7: 143224.09 | F7: 145173.45 | G7: 147214.07 | H7: 148934.05 | I7: 150571.13 | J7: 152152.3 | K7: 153747.5 | L7: 155349.42 | M7: 157022.74 | N7: 158688.32 | O7: 160366.75 | P7: 162061.72 | Q7: 163763.55 | R7: 165479.01
A8: 21 | B8: 2134 | C8: Programmers and software development professionals | D8: 471632.45 | E8: 477240.91 | F8: 483736.44 | G8: 490536.05 | H8: 496267.24 | I8: 501722.19 | J8: 506990.84 | K8: 512306.26 | L8: 517644.07 | M8: 523219.79 | N8: 528769.7 | O8: 534362.46 | P8: 540010.29 | Q8: 545681.01 | R8: 551397.16
A9: 21 | B9: 2135 | C9: Cyber security professionals | D9: 34245.903 | E9: 34653.141 | F9: 35124.791 | G9: 35618.52 | H9: 36034.67 | I9: 36430.761 | J9: 36813.326 | K9: 37199.286 | L9: 37586.872 | M9: 37991.733 | N9: 38394.72 | O9: 38800.818 | P9: 39210.915 | Q9: 39622.674 | R9: 40037.732
A10: 21 | B10: 2136 | C10: IT quality and testing professionals | D10: 32583.629 | E10: 32971.101 | F10: 33419.857 | G10: 33889.62 | H10: 34285.571 | I10: 34662.436 | J10: 35026.431 | K10: 35393.657 | L10: 35762.43 | M10: 36147.639 | N10: 36531.066 | O10: 36917.452 | P10: 37307.643 | Q10: 37699.416 | R10: 38094.327
A11: 21 | B11: 2137 | C11: IT network professionals | D11: 33216.023 | E11: 33611.014 | F11: 34068.48 | G11: 34547.361 | H11: 34950.997 | I11: 35335.176 | J11: 35706.236 | K11: 36080.589 | L11: 36456.519 | M11: 36849.204 | N11: 37240.072 | O11: 37633.958 | P11: 38031.722 | Q11: 38431.098 | R11: 38833.674
A12: 21 | B12: 2139 | C12: Information technology professionals n.e.c. | D12: 139762.49 | E12: 141424.49 | F12: 143349.36 | G12: 145364.34 | H12: 147062.71 | I12: 148679.22 | J12: 150240.52 | K12: 151815.68 | L12: 153397.47 | M12: 155049.77 | N12: 156694.42 | O12: 158351.76 | P12: 160025.43 | Q12: 161705.88 | R12: 163399.79
A13: 21 | B13: 2141 | C13: Web design professionals | D13: 32259.752 | E13: 32643.371 | F13: 33087.667 | G13: 33552.761 | H13: 33944.776 | I13: 34317.896 | J13: 34678.273 | K13: 35041.848 | L13: 35406.956 | M13: 35788.336 | N13: 36167.951 | O13: 36550.497 | P13: 36936.809 | Q13: 37324.688 | R13: 37715.674
A14: 31 | B14: 3131 | C14: IT operations technicians | D14: 115929.23 | E14: 116850.37 | F14: 117968.09 | G14: 119160.44 | H14: 120097.62 | I14: 120962.77 | J14: 121782.42 | K14: 122611.23 | L14: 123444.24 | M14: 124330.63 | N14: 125209.8 | O14: 126097.33 | P14: 126996.86 | Q14: 127900.34 | R14: 128812.86
A15: 31 | B15: 3132 | C15: IT user support technicians | D15: 97466.749 | E15: 98241.196 | F15: 99180.905 | G15: 100183.37 | H15: 100971.3 | I15: 101698.67 | J15: 102387.79 | K15: 103084.6 | L15: 103784.95 | M15: 104530.17 | N15: 105269.33 | O15: 106015.51 | P15: 106771.79 | Q15: 107531.38 | R15: 108298.58
A16: 31 | B16: 3133 | C16: Database administrators and web content technicians | D16: 73066.8 | E16: 73647.371 | F16: 74351.832 | G16: 75103.337 | H16: 75694.018 | I16: 76239.295 | J16: 76755.898 | K16: 77278.268 | L16: 77803.295 | M16: 78361.957 | N16: 78916.073 | O16: 79475.457 | P16: 80042.402 | Q16: 80611.841 | R16: 81186.978
A17: 35 | B17: 3544 | C17: Data analysts | D17: 120549.87 | E17: 121234.66 | F17: 122102.35 | G17: 123049.98 | H17: 123733.28 | I17: 124328.87 | J17: 124875.43 | K17: 125421.84 | L17: 125966.64 | M17: 126556.31 | N17: 127133.8 | O17: 127713.35 | P17: 128299.38 | Q17: 128883.22 | R17: 129469.6
A19: Table 6: Employment by occupation (SOC2020 unit group), technical opportunities scenario, 2021 to 2035, United Kingdom
A20: SOC2020 sub-major group | B20: SOC2020 unit group | C20: Occupation description | D20: 2021 | E20: 2022 | F20: 2023 | G20: 2024 | H20: 2025 | I20: 2026 | J20: 2027 | K20: 2028 | L20: 2029 | M20: 2030 | N20: 2031 | O20: 2032 | P20: 2033 | Q20: 2034 | R20: 2035
A21: 21 | B21: 2133 | C21: IT business analysts, architects and systems designers | D21: 141836.24 | E21: 145829.16 | F21: 149821.15 | G21: 153721.8 | H21: 157194.52 | I21: 160596.21 | J21: 163938.82 | K21: 167293.44 | L21: 170646.9 | M21: 174075.69 | N21: 177456.32 | O21: 180835.3 | P21: 184218.08 | Q21: 187593.52 | R21: 190974.19
A22: 21 | B22: 2134 | C22: Programmers and software development professionals | D22: 472616.42 | E22: 485921.34 | F22: 499223.17 | G22: 512220.63 | H22: 523792.16 | I22: 535127.04 | J22: 546265.05 | K22: 557443.06 | L22: 568617.23 | M22: 580042.39 | N22: 591307.08 | O22: 602566.25 | P22: 613838.11 | Q22: 625085.5 | R22: 636350.34
A23: 21 | B23: 2135 | C23: Cyber security professionals | D23: 34317.35 | E23: 35283.439 | F23: 36249.304 | G23: 37193.068 | H23: 38033.294 | I23: 38856.335 | J23: 39665.082 | K23: 40476.733 | L23: 41288.105 | M23: 42117.703 | N23: 42935.647 | O23: 43753.192 | P23: 44571.658 | Q23: 45388.347 | R23: 46206.303
A24: 21 | B24: 2136 | C24: IT quality and testing professionals | D24: 32651.609 | E24: 33570.805 | F24: 34489.787 | G24: 35387.742 | H24: 36187.183 | I24: 36970.275 | J24: 37739.765 | K24: 38512.019 | L24: 39284.008 | M24: 40073.338 | N24: 40851.58 | O24: 41629.441 | P24: 42408.179 | Q24: 43185.227 | R24: 43963.48
A25: 21 | B25: 2137 | C25: IT network professionals | D25: 33285.322 | E25: 34222.358 | F25: 35159.176 | G25: 36074.558 | H25: 36889.515 | I25: 37687.806 | J25: 38472.231 | K25: 39259.473 | L25: 40046.445 | M25: 40851.094 | N25: 41644.44 | O25: 42437.399 | P25: 43231.251 | Q25: 44023.379 | R25: 44816.737
A26: 21 | B26: 2139 | C26: Information technology professionals n.e.c. | D26: 140054.08 | E26: 143996.83 | F26: 147938.67 | G26: 151790.3 | H26: 155219.39 | I26: 158578.34 | J26: 161878.95 | K26: 165191.42 | L26: 168502.74 | M26: 171888.45 | N26: 175226.6 | O26: 178563.12 | P26: 181903.4 | Q26: 185236.42 | R26: 188574.62
A27: 21 | B27: 2141 | C27: Web design professionals | D27: 32327.055 | E27: 33237.115 | F27: 34146.962 | G27: 35035.991 | H27: 35827.486 | I27: 36602.794 | J27: 37364.636 | K27: 38129.214 | L27: 38893.53 | M27: 39675.013 | N27: 40445.52 | O27: 41215.649 | P27: 41986.647 | Q27: 42755.97 | R27: 43526.488
A28: 31 | B28: 3131 | C28: IT operations technicians | D28: 116169.53 | E28: 120703.71 | F28: 125238.24 | G28: 129714.43 | H28: 133850.97 | I28: 137937.12 | J28: 141984.51 | K28: 146051.99 | L28: 150128.94 | M28: 154280.97 | N28: 158407.5 | O28: 162542.9 | P28: 166691.89 | Q28: 170843.95 | R28: 175010.17
A29: 31 | B29: 3132 | C29: IT user support technicians | D29: 97668.782 | E29: 101480.86 | F29: 105293.24 | G29: 109056.57 | H29: 112534.34 | I29: 115969.74 | J29: 119372.56 | K29: 122792.27 | L29: 126219.94 | M29: 129710.72 | N29: 133180.08 | O29: 136656.89 | P29: 140145.13 | Q29: 143635.95 | R29: 147138.67
A30: 31 | B30: 3133 | C30: Database administrators and web content technicians | D30: 73218.256 | E30: 76076.016 | F30: 78933.995 | G30: 81755.212 | H30: 84362.35 | I30: 86937.73 | J30: 89488.682 | K30: 92052.297 | L30: 94621.879 | M30: 97238.778 | N30: 99839.612 | O30: 102446.03 | P30: 105061.02 | Q30: 107677.94 | R30: 110303.79
A31: 35 | B31: 3544 | C31: Data analysts | D31: 120821.56 | E31: 121405.93 | F31: 121901.55 | G31: 122277.86 | H31: 122285.97 | I31: 122208.23 | J31: 122072.17 | K31: 121925.38 | L31: 121761.54 | M31: 121628.19 | N31: 121467.56 | O31: 121292.33 | P31: 121107.04 | Q31: 120903.98 | R31: 120691.29
A33: Table 8: Employment by occupation (SOC2020 unit group), human-centric scenario, 2021 to 2035, United Kingdom
A34: SOC2020 sub-major group | B34: SOC2020 unit group | C34: Occupation description | D34: 2021 | E34: 2022 | F34: 2023 | G34: 2024 | H34: 2025 | I34: 2026 | J34: 2027 | K34: 2028 | L34: 2029 | M34: 2030 | N34: 2031 | O34: 2032 | P34: 2033 | Q34: 2034 | R34: 2035
A35: 21 | B35: 2133 | C35: IT business analysts, architects and systems designers | D35: 141764.44 | E35: 145942.69 | F35: 150153.27 | G35: 154280.79 | H35: 157956.45 | I35: 161559.47 | J35: 165104.59 | K35: 168664.16 | L35: 172224.39 | M35: 175862.47 | N35: 179454.02 | O35: 183046.68 | P35: 186644.87 | Q35: 190238.77 | R35: 193840.23
A36: 21 | B36: 2134 | C36: Programmers and software development professionals | D36: 472377.19 | E36: 486299.63 | F36: 500329.83 | G36: 514083.26 | H36: 526331.02 | I36: 538336.73 | J36: 550149.52 | K36: 562010.48 | L36: 573873.61 | M36: 585996.16 | N36: 597963.66 | O36: 609934.85 | P36: 621924.48 | Q36: 633899.83 | R36: 645900.33
A37: 21 | B37: 2135 | C37: Cyber security professionals | D37: 34299.979 | E37: 35310.908 | F37: 36329.661 | G37: 37328.316 | H37: 38217.644 | I37: 39089.395 | J37: 39947.139 | K37: 40808.38 | L37: 41669.779 | M37: 42550.014 | N37: 43418.991 | O37: 44288.237 | P37: 45158.821 | Q37: 46028.368 | R37: 46899.742
A38: 21 | B38: 2136 | C38: IT quality and testing professionals | D38: 32635.081 | E38: 33596.94 | F38: 34566.243 | G38: 35516.425 | H38: 36362.585 | I38: 37192.022 | J38: 38008.131 | K38: 38827.569 | L38: 39647.155 | M38: 40484.665 | N38: 41311.462 | O38: 42138.515 | P38: 42966.842 | Q38: 43794.181 | R38: 44623.259
A39: 21 | B39: 2137 | C39: IT network professionals | D39: 33268.473 | E39: 34249 | F39: 35237.116 | G39: 36205.739 | H39: 37068.321 | I39: 37913.857 | J39: 38745.805 | K39: 39581.146 | L39: 40416.64 | M39: 41270.404 | N39: 42113.249 | O39: 42956.353 | P39: 43800.756 | Q39: 44644.153 | R39: 45489.322
A40: 21 | B40: 2139 | C40: Information technology professionals n.e.c. | D40: 139983.19 | E40: 144108.93 | F40: 148266.61 | G40: 152342.27 | H40: 155971.74 | I40: 159529.49 | J40: 163030.07 | K40: 166544.92 | L40: 170060.41 | M40: 173652.78 | N40: 177199.2 | O40: 180746.72 | P40: 184299.69 | Q40: 187848.44 | R40: 191404.64
A41: 21 | B41: 2141 | C41: Web design professionals | D41: 32310.692 | E41: 33262.99 | F41: 34222.658 | G41: 35163.396 | H41: 36001.145 | I41: 36822.338 | J41: 37630.335 | K41: 38441.627 | L41: 39253.067 | M41: 40082.252 | N41: 40900.831 | O41: 41719.663 | P41: 42539.756 | Q41: 43358.872 | R41: 44179.709
A42: 31 | B42: 3131 | C42: IT operations technicians | D42: 116120.97 | E42: 119953.82 | F42: 123803.33 | G42: 127592.53 | H42: 131020.42 | I42: 134393.32 | J42: 137726.03 | K42: 141076.75 | L42: 144434.92 | M42: 147863.58 | N42: 151267.85 | O42: 154680.52 | P42: 158105.42 | Q42: 161533.98 | R42: 164976.07
A43: 31 | B43: 3132 | C43: IT user support technicians | D43: 97627.952 | E43: 100850.4 | F43: 104086.85 | G43: 107272.6 | H43: 110154.57 | I43: 112990.31 | J43: 115792.27 | K43: 118609.37 | L43: 121432.72 | M43: 124315.35 | N43: 127177.47 | O43: 130046.65 | P43: 132926.11 | Q43: 135808.65 | R43: 138702.56
...

Sheet 06_Career_Area_Map
A1: This table provides the operational SOC-to-Career-Area mapping used to aggregate the official employment projections into the five Computer Science Career Areas. The classification, mixed-SOC methodology and Adzuna-derived allocation calculations are documented in the Career Map & Curriculum Alignment Supporting Workbook, saved on: https://docs.google.com/spreadsheets/d/16bBDBk5eAcaZsfU9kJ7sDSBoUj7RSggH/edit?usp=sharing
A2: Career Area | B2: SOC Unit Group / Sub-Unit | C2: Occupation | D2: Share / Treatment
A3: 1. Software Development & Testing | B3: 2134 | C3: Programmers and software development professionals | D3: Full Unit Group
B4: 2136 | C4: IT quality and testing professionals | D4: Full Unit Group
B5: 2139/01 | C5: DevOps engineers | D5: 46.1% of validated 2139 results
A6: 2. Data, Analytics & Databases | B6: 3544 | C6: Data analysts | D6: Full Unit Group
B7: 3133 | C7: Database administrators and web content technicians | D7: Full Unit Group
B8: 2133/02 + 2133/03 | C8: Data architects + Data engineers | D8: 64.5% of validated 2133 results
A9: 3. Cybersecurity | B9: 2135 | C9: Cyber security professionals | D9: Full Unit Group
A10: 4. Web, Applications & UX/UI | B10: 2141 | C10: Web design professionals | D10: Full Unit Group
B11: 2139/03 | C11: Webmasters / Website managers | D11: 29.0% of validated 2139 results
A12: 5. IT Infrastructure, Networks & Support | B12: 2137 | C12: IT network professionals | D12: Full Unit Group
B13: 3131 | C13: IT operations technicians | D13: Full Unit Group
B14: 3132 | C14: IT user support technicians | D14: Full Unit Group
B15: 2133/04 + 2133/06 | C15: Systems architects + Solution architects | D15: 29.9% of validated 2133 results
A16: Cross-functional / Mixed IT | B16: 2133/01 + 2133/05 | C16: Systems analysts + IT business analysts | D16: 5.6% of validated 2133 results
B17: 2139/02 | C17: IT consultants | D17: 24.9% of validated 2139 results
A18: Mixed SOC Note: SOC 2133 and 2139 span multiple Career Areas and are therefore proportionally allocated using the validated Adzuna vacancy-search shares documented in the supporting Career Map workbook. These shares are methodological proxies and are not official SOC employment weights.
A22: Application: Full Unit Groups are allocated at 100% to their mapped Career Area, while the documented proportional shares are applied to 2133 and 2139 consistently across all years and projection scenarios.

Sheet 07_Analysis_Base
A1: Analysis Base
A2: Consolidated analytical dataset combining the three official employment projection scenarios with the final Career Area mapping and mixed-SOC allocation rules
A3: Scenario Use: Baseline is the primary reference scenario for the main employment growth analysis. Technical Opportunities and Human-Centric are retained as alternative scenarios for comparative analysis of future employment trajectories.
A5: Scenario | B5: SOC Unit Group | C5: Year | D5: Occupation | E5: Career Area | F5: Allocation Share | G5: Original Employment | H5: Allocated Employment | I5: Treatment
A6: Baseline | B6: 2135 | C6: 2021 | D6: Cyber security professionals | E6: Cybersecurity | F6: 1 | G6: 34245.903 | H6: =G6*F6 -> 34245.903 | I6: Full Unit Group
A7: Baseline | B7: 2135 | C7: 2022 | D7: Cyber security professionals | E7: Cybersecurity | F7: 1 | G7: 34653.141 | H7: =G7*F7 -> 34653.141 | I7: Full Unit Group
A8: Baseline | B8: 2135 | C8: 2023 | D8: Cyber security professionals | E8: Cybersecurity | F8: 1 | G8: 35124.791 | H8: =G8*F8 -> 35124.791 | I8: Full Unit Group
A9: Baseline | B9: 2135 | C9: 2024 | D9: Cyber security professionals | E9: Cybersecurity | F9: 1 | G9: 35618.52 | H9: =G9*F9 -> 35618.52 | I9: Full Unit Group
A10: Baseline | B10: 2135 | C10: 2025 | D10: Cyber security professionals | E10: Cybersecurity | F10: 1 | G10: 36034.67 | H10: =G10*F10 -> 36034.67 | I10: Full Unit Group
A11: Baseline | B11: 2135 | C11: 2026 | D11: Cyber security professionals | E11: Cybersecurity | F11: 1 | G11: 36430.761 | H11: =G11*F11 -> 36430.761 | I11: Full Unit Group
A12: Baseline | B12: 2135 | C12: 2027 | D12: Cyber security professionals | E12: Cybersecurity | F12: 1 | G12: 36813.326 | H12: =G12*F12 -> 36813.326 | I12: Full Unit Group
A13: Baseline | B13: 2135 | C13: 2028 | D13: Cyber security professionals | E13: Cybersecurity | F13: 1 | G13: 37199.286 | H13: =G13*F13 -> 37199.286 | I13: Full Unit Group
A14: Baseline | B14: 2135 | C14: 2029 | D14: Cyber security professionals | E14: Cybersecurity | F14: 1 | G14: 37586.872 | H14: =G14*F14 -> 37586.872 | I14: Full Unit Group
A15: Baseline | B15: 2135 | C15: 2030 | D15: Cyber security professionals | E15: Cybersecurity | F15: 1 | G15: 37991.733 | H15: =G15*F15 -> 37991.733 | I15: Full Unit Group
A16: Baseline | B16: 2135 | C16: 2031 | D16: Cyber security professionals | E16: Cybersecurity | F16: 1 | G16: 38394.72 | H16: =G16*F16 -> 38394.72 | I16: Full Unit Group
A17: Baseline | B17: 2135 | C17: 2032 | D17: Cyber security professionals | E17: Cybersecurity | F17: 1 | G17: 38800.818 | H17: =G17*F17 -> 38800.818 | I17: Full Unit Group
... A680: Human-Centric | B680: 2139 | C680: 2035 | D680: Information technology professionals n.e.c. | E680: Cross-functional / Mixed IT | F680: 0.249 | G680: 191404.64 | H680: =G680*F680 -> 47659.757 | I680: Mixed SOC Allocation
A684: Career Area Annual Aggregation
A685: Aggregated from Allocated Employment by Scenario, Year and Career Area. Cross-functional / Mixed IT is retained for reconciliation but is not treated as one of the five primary Career Areas.
A687: Scenario | B687: Year | C687: Career Area | D687: Total Allocated Employment
A688: Baseline | B688: 2021 | C688: Software Development & Testing | D688: =SUMIFS($H$6:$H$680,$A$6:$A$680,A688,$C$6:$C$680,B688,$E$6:$E$680,C688) -> 568646.59
A689: Baseline | B689: 2021 | C689: Data, Analytics & Databases | D689: =SUMIFS($H$6:$H$680,$A$6:$A$680,A689,$C$6:$C$680,B689,$E$6:$E$680,C689) -> 284910.57
A690: Baseline | B690: 2021 | C690: Cybersecurity | D690: =SUMIFS($H$6:$H$680,$A$6:$A$680,A690,$C$6:$C$680,B690,$E$6:$E$680,C690) -> 34245.903
A691: Baseline | B691: 2021 | C691: Web, Applications & UX/UI | D691: =SUMIFS($H$6:$H$680,$A$6:$A$680,A691,$C$6:$C$680,B691,$E$6:$E$680,C691) -> 72790.875
A692: Baseline | B692: 2021 | C692: IT Infrastructure, Networks & Support | D692: =SUMIFS($H$6:$H$680,$A$6:$A$680,A692,$C$6:$C$680,B692,$E$6:$E$680,C692) -> 288932.74
A693: Baseline | B693: 2021 | C693: Cross-functional / Mixed IT | D693: =SUMIFS($H$6:$H$680,$A$6:$A$680,A693,$C$6:$C$680,B693,$E$6:$E$680,C693) -> 42727.154
A694: Baseline | B694: 2022 | C694: Software Development & Testing | D694: =SUMIFS($H$6:$H$680,$A$6:$A$680,A694,$C$6:$C$680,B694,$E$6:$E$680,C694) -> 575408.7
A695: Baseline | B695: 2022 | C695: Data, Analytics & Databases | D695: =SUMIFS($H$6:$H$680,$A$6:$A$680,A695,$C$6:$C$680,B695,$E$6:$E$680,C695) -> 287261.57
A696: Baseline | B696: 2022 | C696: Cybersecurity | D696: =SUMIFS($H$6:$H$680,$A$6:$A$680,A696,$C$6:$C$680,B696,$E$6:$E$680,C696) -> 34653.141
A697: Baseline | B697: 2022 | C697: Web, Applications & UX/UI | D697: =SUMIFS($H$6:$H$680,$A$6:$A$680,A697,$C$6:$C$680,B697,$E$6:$E$680,C697) -> 73656.474
A698: Baseline | B698: 2022 | C698: IT Infrastructure, Networks & Support | D698: =SUMIFS($H$6:$H$680,$A$6:$A$680,A698,$C$6:$C$680,B698,$E$6:$E$680,C698) -> 291526.59
A699: Baseline | B699: 2022 | C699: Cross-functional / Mixed IT | D699: =SUMIFS($H$6:$H$680,$A$6:$A$680,A699,$C$6:$C$680,B699,$E$6:$E$680,C699) -> 43235.247
... A957: Human-Centric | B957: 2035 | C957: Cross-functional / Mixed IT | D957: =SUMIFS($H$6:$H$680,$A$6:$A$680,A957,$C$6:$C$680,B957,$E$6:$E$680,C957) -> 58514.809

Sheet 08_WEF_Technology
A1: WEF Technology Trends — Extracted / Structured Data from the United Kingdom Economy Profile, Future of Jobs Report 2025
A2: ID | B2: Technology Trend driving business transformation | C2: Category | D2: UK (%) | E2: Global (%) | F2: Difference (UK - Global) | G2: Net Effect (Million Jobs) | H2: Primary Related Area | I2: Use in Analysis | J2: Notes
A3: 1 | B3: AI and information processing technologies (Big Data, Virtual Reality, Augmented Reality, etc.) | C3: Technology Driver | D3: 92 | E3: 86 | F3: =D3-E3 -> 6 | G3: 1.8 | H3: Data, Analytics & Databases | I3: Yes | J3: Main driving technology.
A4: 2 | B4: Robots and autonomous systems | C4: Technology Driver | D4: 62 | E4: 58 | F4: =D4-E4 -> 4 | G4: -4.8 | H4: Software Development & Testing | I4: Yes | J4: Automation and applied AI.
A5: 3 | B5: Energy generation, storage and distribution | C5: Technology Driver | D5: 40 | E5: 41 | F5: =D5-E5 -> -1 | G5: 1 | H5: Outside Scope | I5: No | J5: Not directly related to the five areas.
A6: 4 | B6: Semiconductors and computing technologies | C6: Technology Driver | D6: 33 | E6: 20 | F6: =D6-E6 -> 13 | G6: 0.6 | H6: IT Infrastructure, Networks & Support | I6: Yes | J6: Infrastructure, hardware, and cloud computing.
A7: 5 | B7: New materials and composites | C7: Technology Driver | D7: 32 | E7: 30 | F7: =D7-E7 -> 2 | G7: 0.9 | H7: Outside Scope | I7: No | J7: Focus on materials engineering.
A8: 6 | B8: Sensing, laser and optical technologies | C8: Technology Driver | D8: 24 | E8: 18 | F8: =D8-E8 -> 6 | G8: 0.1 | H8: Outside Scope | I8: No | J8: Limited relevance to the project.
A9: 7 | B9: Quantum and encryption | C9: Technology Driver | D9: 23 | E9: 12 | F9: =D9-E9 -> 11 | G9: 0.3 | H9: Cybersecurity | I9: Yes | J9: Strong connection to information security.
A10: 8 | B10: Biotechnology and gene technologies | C10: Technology Driver | D10: 15 | E10: 11 | F10: =D10-E10 -> 4 | G10: 0.2 | H10: Outside Scope | I10: No | J10: Not related to the project's focus.
A11: 9 | B11: Satellites and space technologies | C11: Technology Driver | D11: 10 | E11: 9 | F11: =D11-E11 -> 1 | G11: 0.1 | H11: Outside Scope | I11: No | J11: Low relevance to the five areas.
A12: The UK (%) and Global (%) values were extracted from the "Technology Trends" section of the WEF Economy Profile – United Kingdom.
A13: Source: World Economic Forum, Future of Jobs Report 2025, United Kingdom Economy Profile. https://www.weforum.org/publications/the-future-of-jobs-report-2025/
A14: The Net Effect (Million Jobs) values were extracted from Figure 2.6 – "Expected impact of macrotrends and technology trends on jobs, 2025–2030" of the WEF Future of Jobs Report 2025.
A15: Net Effect (Million Jobs): The overall change in employment after subtracting jobs lost from jobs created, measured in millions of jobs, is global WEF contextual evidence and is not used in the UK–Global regression or as a direct measure of Computer Science employment.

Sheet 09_WEF_Jobs_Outlook
A1: WEF Jobs Outlook — Extracted / Structured Data from the United Kingdom Economy Profile, Future of Jobs Report 2025
A2: ID | B2: Occupation | C2: UK Net Growth (%) | D2: Global Net Growth (%) | E2: Structural Churn (%) | F2: Primary Related Area | G2: Use in Analysis | H2: Notes
A3: 1 | B3: Big Data Specialists | C3: 319 | D3: 113 | E3: 320 | F3: Data, Analytics & Databases | G3: Yes | H3: Highest net growth in the United Kingdom.
A4: 2 | B4: AI and Machine Learning Specialists | C4: 151 | D4: 82 | E4: 151 | F4: Data, Analytics & Databases | G4: Yes | H4: AI is one of the main drivers of these careers.
A5: 3 | B5: Data Analysts and Scientists | C5: 29 | D5: 41 | E5: 29 | F5: Data, Analytics & Databases | G5: Yes | H5: Directly related to data analytics.
A6: 4 | B6: Business Development Professionals | C6: 14 | D6: 19 | E6: 15 | F6: Outside Scope | G6: No | H6: Outside the five Computer Science areas.
A7: 5 | B7: General and Operations Managers | C7: -4 | D7: 4 | E7: 9 | F7: Outside Scope | G7: No | H7: Management role; does not represent a technical specialization.
A8: 6 | B8: Data Entry Clerks | C8: -26 | D8: -26 | E8: 26 | F8: Outside Scope | G8: No | H8: Declining occupation; does not represent Data Analytics.
A9: Source: World Economic Forum, Future of Jobs Report 2025, United Kingdom Economy Profile. https://www.weforum.org/publications/the-future-of-jobs-report-2025/
A10: Source Note: World Economic Forum, Future of Jobs Report 2025 — United Kingdom Economy Profile, “Jobs outlook – Key roles for business transformation”.
A11: Analytical Note: WEF Jobs Outlook values are survey-based percentage indicators of expected occupational change and are used as complementary future-trend evidence. They are not employment counts and are not directly combined with the official DfE employment projections.
A12: Net Growth (%): The projected net change in employment for the occupation, expressed as a percentage. Positive values indicate growth, while negative values indicate decline.
A13: Structural Churn (%): The combined scale of job growth and job displacement associated with the occupation, indicating the expected degree of employment transformation.

Sheet 10_WEF_AI_Strategy
A1: WEF AI Strategy — Extracted / Structured Data from the United Kingdom Economy Profile, Future of Jobs Report 2025
A2: ID | B2: AI Strategy | C2: Category | D2: UK (%) | E2: Global (%) | F2: Difference (UK - Global) | G2: Primary Related Area | H2: Use in Analysis | I2: Notes
A3: 1 | B3: Reskilling and upskilling the existing workforce to better work alongside AI | C3: Workforce Development | D3: 90 | E3: 77 | F3: =D3-E3 -> 13 | G3: All Areas | H3: Yes | I3: Primary strategy adopted by organizations in the United Kingdom.
A4: 2 | B4: Hiring new people with skills to design AI tools and enhancements appropriate for the organization | C4: AI Talent Acquisition | D4: 74 | E4: 69 | F4: =D4-E4 -> 5 | G4: Data, Analytics & Databases | H4: Yes | I4: Demonstrates strong demand for AI-related skills.
A5: 3 | B5: Hiring new people with skills to better work alongside AI | C5: AI Workforce Integration | D5: 66 | E5: 62 | F5: =D5-E5 -> 4 | G5: All Areas | H5: Yes | I5: Reinforces the need for skills to work with AI.
A6: Source: World Economic Forum, Future of Jobs Report 2025, United Kingdom Economy Profile. https://www.weforum.org/publications/the-future-of-jobs-report-2025/
A7: Source Note: Data extracted from the AI Strategy section of the World Economic Forum, Future of Jobs Report 2025 — United Kingdom Economy Profile.

Sheet 11_WEF_Skills_Outlook
A1: WEF Skills Outlook — Extracted / Structured Data from the United Kingdom Economy Profile, Future of Jobs Report 2025
A2: Core Skills of 2025
A3: ID | B3: Skill | C3: Category | D3: UK (%) | E3: Global position vs UK | F3: Primary Related Area | G3: Use in Analysis | H3: Notes
A4: 1 | B4: Analytical thinking | C4: Core Skill (2025) | D4: 80 | E4: Below UK | F4: All Areas | G4: Yes | H4: Cross-cutting skill across all Computer Science areas.
A5: 2 | B5: Resilience, flexibility and agility | C5: Core Skill (2025) | D5: 73 | E5: Below UK | F5: All Areas | G5: Yes | H5: Important for adapting to technological change.
A6: 3 | B6: Leadership and social influence | C6: Core Skill (2025) | D6: 65 | E6: Below UK | F6: All Areas | G6: Partial | H6: Complementary skill.
A7: 4 | B7: Creative thinking | C7: Core Skill (2025) | D7: 62 | E7: Below UK | F7: Web, Applications & UX/UI | G7: Yes | H7: Particularly relevant to UX/UI, but valuable across all areas.
A8: 5 | B8: Motivation and self-awareness | C8: Core Skill (2025) | D8: 56 | E8: Below UK | F8: All Areas | G8: Partial | H8: Behavioral skill.
A10: Skills of Increasing Use by 2030
A11: ID | B11: Skill | C11: Category | D11: UK (%) | E11: Global position vs UK | F11: Primary Related Area | G11: Use in Analysis | H11: Notes
A12: 6 | B12: AI and big data | C12: Increasing Skill (2030) | D12: 92 | E12: Below UK | F12: Data, Analytics & Databases | G12: Yes | H12: Technical skill with the highest expected growth.
A13: 7 | B13: Networks and cybersecurity | C13: Increasing Skill (2030) | D13: 71 | E13: Slightly above UK | F13: Cybersecurity | G13: Yes | H13: Directly related to information security.
A14: 8 | B14: Technological literacy | C14: Increasing Skill (2030) | D14: 71 | E14: Approximately aligned with UK | F14: All Areas | G14: Yes | H14: Cross-cutting skill; the exact Global percentage is not numerically reported, although the Global benchmark is shown graphically.
A15: 9 | B15: Resilience, flexibility and agility | C15: Increasing Skill (2030) | D15: 69 | E15: Slightly below UK | F15: All Areas | G15: Partial | H15: Important behavioral skill.
A16: 10 | B16: Curiosity and lifelong learning | C16: Increasing Skill (2030) | D16: 68 | E16: Below UK | F16: All Areas | G16: Yes | H16: Essential for keeping pace with technological advancement.
A17: Source: World Economic Forum, Future of Jobs Report 2025, United Kingdom Economy Profile. https://www.weforum.org/publications/the-future-of-jobs-report-2025/
A18: Source Note: Data extracted from the Skill Outlook section of the World Economic Forum, Future of Jobs Report 2025 — United Kingdom Economy Profile.
A19: Global Comparison Note: Exact Global percentages are not numerically reported in the source. Global benchmarks are displayed graphically using markers; therefore, the comparison is recorded qualitatively as above, below or approximately aligned with the UK value rather than estimating exact percentages.

Sheet 12_WEF_Fastest_Growing
A1: WEF Fastest-Growing Jobs — Extracted / Structured Data from the Future of Jobs Report 2025
A2: Rank | B2: Occupation | C2: Primary Related Area | D2: In Scope
A3: 1 | B3: Big Data Specialists | C3: Data, Analytics & Databases | D3: Yes
A4: 2 | B4: FinTech Engineers | C4: Software Development & Testing | D4: Yes
A5: 3 | B5: AI and Machine Learning Specialists | C5: Data, Analytics & Databases | D5: Yes
A6: 4 | B6: Software and Applications Developers | C6: Software Development & Testing | D6: Yes
A7: 5 | B7: Security Management Specialists | C7: Cybersecurity | D7: Yes
A8: 6 | B8: Data Warehousing Specialists | C8: Data, Analytics & Databases | D8: Yes
A9: 7 | B9: Autonomous and Electric Vehicle Specialists | C9: Outside Scope | D9: No
A10: 8 | B10: UI and UX Designers | C10: Web, Applications & UX/UI | D10: Yes
A11: 9 | B11: Light Truck or Delivery Services Drivers | C11: Outside Scope | D11: No
A12: 10 | B12: Internet of Things Specialists | C12: IT Infrastructure, Networks & Support | D12: Yes
A13: 11 | B13: Data Analysts and Scientists | C13: Data, Analytics & Databases | D13: Yes
A14: 12 | B14: Environmental Engineers | C14: Outside Scope | D14: No
... A17: 15 | B17: Renewable Energy Engineers | C17: Outside Scope | D17: No
A18: Source: World Economic Forum, Future of Jobs Report 2025, Figure 2.2, “Fastest-growing and fastest-declining jobs, 2025–2030”. https://www.weforum.org/publications/the-future-of-jobs-report-2025/
A19: Source Note: Data extracted from Figure 2.2, “Fastest-growing and fastest-declining jobs, 2025–2030”, World Economic Forum, Future of Jobs Report 2025.
A20: Scope Note: Figure 2.2 presents global fastest-growing occupations based on the WEF Future of Jobs Survey 2024. It is used as complementary global evidence of occupational growth trends and should not be interpreted as a UK-specific employment projection.

Sheet 13_Descriptive_Q1
A1: Field | B1: Content | H1: Between 2025 and 2035, all five Computer Science Career Areas are projected to increase employment under the Baseline scenario. Software Development & Testing shows the largest absolute job creation (+66,470 jobs) and one of the highest proportional growth rates (11.1%). Cybersecurity and Web, Applications & UX/UI also show approximately 11.1% growth, but their smaller employment bases result in lower absolute job creation. IT Infrastructure, Networks & Support and Data, Analytics & Databases show lower proportional growth of 8.3% and 7.4%, respectively, while still adding more jobs in absolute terms than some faster-growing smaller areas.
A2: Analytics Type | B2: Descriptive
A3: Research Question | B3: Q1. How do employment growth and job creation differ across the five Career Areas?
A4: Purpose | B4: Compare employment scale, absolute job creation and percentage growth across the five Career Areas.
A5: Method(s) | B5: Descriptive Analysis; Absolute Growth; Growth %
A6: Dataset(s) | B6: 07_Analysis_Base — Baseline scenario
A7: Unit of Analysis | B7: Career Area
A8: Comparison Period | B8: 2025–2035
A10: Reconciliation Note: Cross-functional / Mixed IT is retained in the Analysis Base for reconciliation of mixed SOC allocations but is excluded from the five-Career-Area comparison presented in Q1.
A11: Methodological Note: Employment totals use the Career Area allocations prepared in 07_Analysis_Base. Mixed SOC Unit Groups 2133 and 2139 are proportionally allocated using the documented Adzuna methodological proxy; these shares are not official SOC employment weights.
B16: Area Computer Science | C16: 2025 Employment | D16: 2035 Employment | E16: Growth % | F16: Absolute Growth | H16: Which of the five CS Career Areas are projected to show the strongest employment growth between 2025 and 2035?
B17: Software Development & Testing | C17: 598348.73 | D17: 664818.79 | E17: =(D17-C17)/C17 -> 0.11108918 | F17: =D17-C17 -> 66470.067
B18: Cybersecurity | C18: 36034.67 | D18: 40037.732 | E18: =(D18-C18)/C18 -> 0.11108918 | F18: =D18-C18 -> 4003.0618
B19: Web, Applications & UX/UI | C19: 76592.963 | D19: 85101.612 | E19: =(D19-C19)/C19 -> 0.11108918 | F19: =D19-C19 -> 8508.6492
B20: IT Infrastructure, Networks & Support | C20: 300551.2 | D20: 325423.34 | E20: =(D20-C20)/C20 -> 0.082755087 | F20: =D20-C20 -> 24872.141
B21: Data, Analytics & Databases | C21: 295489.76 | D21: 317390.55 | E21: =(D21-C21)/C21 -> 0.074116912 | F21: =D21-C21 -> 21900.789
H38: Source: Author’s calculations based on Department for Education employment projections, Baseline scenario.
H39: Software Development & Testing, Cybersecurity, and Web, Applications & UX/UI show the strongest projected employment growth, each increasing by approximately 11.1% between 2025 and 2035. IT Infrastructure, Networks & Support is also expected to grow at 8.28%, while Data, Analytics & Databases shows the lowest projected growth among the five Career Areas, at 7.41%.
B46: Area Computer Science | C46: 2025 Employment | D46: 2035 Employment | E46: Growth % | F46: Absolute Growth | H46: Which of the five CS Career Areas are projected to create the largest number of additional jobs between 2025 and 2035?
B47: Software Development & Testing | C47: 598348.73 | D47: 664818.79 | E47: =(D47-C47)/C47 -> 0.11108918 | F47: =D47-C47 -> 66470.067
B48: IT Infrastructure, Networks & Support | C48: 300551.2 | D48: 325423.34 | E48: =(D48-C48)/C48 -> 0.082755087 | F48: =D48-C48 -> 24872.141
B49: Data, Analytics & Databases | C49: 295489.76 | D49: 317390.55 | E49: =(D49-C49)/C49 -> 0.074116912 | F49: =D49-C49 -> 21900.789
B50: Web, Applications & UX/UI | C50: 76592.963 | D50: 85101.612 | E50: =(D50-C50)/C50 -> 0.11108918 | F50: =D50-C50 -> 8508.6492
B51: Cybersecurity | C51: 36034.67 | D51: 40037.732 | E51: =(D51-C51)/C51 -> 0.11108918 | F51: =D51-C51 -> 4003.0618
H66: Source: Author’s calculations based on Department for Education employment projections, Baseline scenario.
H67: Software Development & Testing is projected to create the largest number of additional jobs between 2025 and 2035, adding approximately 66,470 positions. IT Infrastructure, Networks & Support follows with around 24,872 additional jobs, while Data, Analytics & Databases is projected to add approximately 21,901. Although Web, Applications & UX/UI and Cybersecurity show strong proportional growth, their smaller employment bases result in lower absolute job creation of approximately 8,509 and 4,003 jobs, respectively.

Sheet 14_Predictive_Q2
A1: Section 1 — Analytical Framework
A2: Field | B2: Content
A3: Analytics Type | B3: Predictive-oriented
A4: Research Question | B4: Q2. How do employment projections change over time and across future scenarios?
A5: Purpose | B5: Examine long-term employment projections across the five Career Areas and alternative future scenarios, and complement these projections with an exploratory short-term forecast based on recent Annual Population Survey (APS) employment estimates.
A6: Method(s) | B6: Time Series Analysis; 2-Year Moving Average; Simple Exponential Smoothing; MSE Model Comparison; Scenario Comparison
A7: Dataset(s) | B7: 07_Analysis_Base — DfE Baseline, Technical Opportunities and Human-Centric projections; 14A — ONS Annual Population Survey employment estimates, 2021–2025
A8: Unit of Analysis | B8: Career Area by Year and Scenario; Career Area for short-term forecast comparison
A9: Period | B9: DfE projections: 2021–2035; APS estimates: 2021–2025; exploratory forecast: 2026
A10: Methodological Note: This analysis combines externally produced DfE employment projections with an exploratory short-term forecast generated from ONS APS employment estimates for 2021–2025. A 2-year Moving Average and Simple Exponential Smoothing (α = 0.2, 0.5 and 0.8) were evaluated using Mean Squared Error (MSE) over the common validation period 2023–2025. The best-performing method for each Career Area was used to generate a 2026 forecast. Due to the short five-year time series, the forecast is exploratory and is not extended to 2035. Mixed SOC Unit Groups 2133 and 2139 use the proportional allocations already applied in 07_Analysis_Base. The Q3 regression was used to examine the Global–UK relationship rather than to forecast employment and was therefore not included in the MSE model comparison.
A11: Reconciliation Note: Cross-functional / Mixed IT is retained in the Analysis Base for reconciliation but excluded from the five-Career-Area comparison.
A12: Model Selection Result: Simple Exponential Smoothing (SES) with α = 0.8 produced the lowest MSE for Software Development & Testing, Data, Analytics & Databases, Cybersecurity, and IT Infrastructure, Networks & Support. SES with α = 0.2 produced the lowest MSE for Web, Applications & UX/UI. The 2-Year Moving Average did not produce the lowest MSE for any Career Area.
A14: Section 2 — Career Area Time-Series Data
B16: Career Area | C16: Year | D16: Baseline | E16: Technical Opportunities | F16: Human-Centric
B17: Software Development & Testing | C17: 2021 | D17: =SUMIFS('07_Analysis_Base'!$D$688:$D$957,'07_Analysis_Base'!$A$688:$A$957,D$16,'07_Analysis_Base'!$B$688:$B$957,$C17,'07_Analysis_Base'!$C$688:$C$957,$B17) -> 568646.59 | E17: =SUMIFS('07_Analysis_Base'!$D$688:$D$957,'07_Analysis_Base'!$A$688:$A$957,E$16,'07_Analysis_Base'!$B$688:$B$957,$C17,'07_Analysis_Base'!$C$688:$C$957,$B17) -> 569832.96 | F17: =SUMIFS('07_Analysis_Base'!$D$688:$D$957,'07_Analysis_Base'!$A$688:$A$957,F$16,'07_Analysis_Base'!$B$688:$B$957,$C17,'07_Analysis_Base'!$C$688:$C$957,$B17) -> 569544.52
B18: Software Development & Testing | C18: 2022 | D18: =SUMIFS('07_Analysis_Base'!$D$688:$D$957,'07_Analysis_Base'!$A$688:$A$957,D$16,'07_Analysis_Base'!$B$688:$B$957,$C18,'07_Analysis_Base'!$C$688:$C$957,$B18) -> 575408.7 | E18: =SUMIFS('07_Analysis_Base'!$D$688:$D$957,'07_Analysis_Base'!$A$688:$A$957,E$16,'07_Analysis_Base'!$B$688:$B$957,$C18,'07_Analysis_Base'!$C$688:$C$957,$B18) -> 585874.68 | F18: =SUMIFS('07_Analysis_Base'!$D$688:$D$957,'07_Analysis_Base'!$A$688:$A$957,F$16,'07_Analysis_Base'!$B$688:$B$957,$C18,'07_Analysis_Base'!$C$688:$C$957,$B18) -> 586330.79
B19: Software Development & Testing | C19: 2023 | D19: =SUMIFS('07_Analysis_Base'!$D$688:$D$957,'07_Analysis_Base'!$A$688:$A$957,D$16,'07_Analysis_Base'!$B$688:$B$957,$C19,'07_Analysis_Base'!$C$688:$C$957,$B19) -> 583240.36 | E19: =SUMIFS('07_Analysis_Base'!$D$688:$D$957,'07_Analysis_Base'!$A$688:$A$957,E$16,'07_Analysis_Base'!$B$688:$B$957,$C19,'07_Analysis_Base'!$C$688:$C$957,$B19) -> 601912.68 | F19: =SUMIFS('07_Analysis_Base'!$D$688:$D$957,'07_Analysis_Base'!$A$688:$A$957,F$16,'07_Analysis_Base'!$B$688:$B$957,$C19,'07_Analysis_Base'!$C$688:$C$957,$B19) -> 603246.99
